Workbook

Sheet Data original
A1: Fecha,ID_Campaña,Canal,País,Dispositivo,Impresiones,Clics,Conversiones,Gasto_EUR,Ingresos_EUR,Nuevos_Clientes,Tipo_Campaña,Responsable
A2: 2025-07-30,CMP-002,Email,México,Desktop,129041,9255,1081,4728.14,195401.22,926,Adquisición,Carlos Ruiz
A3: 2025-05-02,CMP-009,Paid Search,Italia,Desktop,50677,4047,409,6481.73,65100.85,249,Retención,Luis Martín
A4: 2025-01-05,CMP-009,Email,Francia,Desktop,12070,959,57,1465.19,7772.79,31,Retención,Laura Pérez
A5: 2025-06-07,CMP-002,Affiliate,España,Mobile,114121,890,114,1196.8,24221.44,52,Adquisición,Luis Martín
A6: 2025-09-16,CMP-026,Paid Search,Portugal,Desktop,123994,5563,308,1315.48,47341.08,254,Adquisición,Luis Martín
A7: 2025-10-04,CMP-022,Paid Social,Portugal,Tablet,170534,7543,96,10662.79,15691.35,51,Adquisición,Carlos Ruiz
A8: 2025-06-20,CMP-015,Email,Francia,Tablet,84579,3855,121,7967.14,12733.03,58,Reconocimiento,Marta López
A9: 2025-10-11,CMP-004,Affiliate,Portugal,Mobile,125454,7459,507,14866.14,74384.02,356,Conversión,Laura Pérez
A10: 2025-09-08,CMP-017,Paid Search,Portugal,Desktop,147026,2076,174,574.55,13381.79,125,Conversión,Luis Martín
A11: 2025-11-13,CMP-002,Display,Francia,Mobile,8375,469,33,672.99,5104.23,18,Conversión,Marta López
A12: 2025-06-30,CMP-025,Organic Social,España,Desktop,169640,13188,1573,3188.1,158029.53,1309,Retención,Luis Martín
... A2536: 2025-05-16,CMP-012,Email,Portugal,Mobile,3038,193,24,303.76,4454.33,18,Adquisición,Luis Martín

Sheet Auditoría 
A1: Fecha | B1: ID_Campaña | C1: Canal | D1: País | E1: Dispositivo | F1: Impresiones | G1: Clics | H1: Conversiones | I1: Gasto_EUR | J1: Ingresos_EUR | K1: Nuevos_Clientes | L1: Tipo_Campaña | M1: Responsable | N1: AUX_ID | O1: AUX_Canal | P1: AUX_País | Q1: AUX_Dispositivo | R1: AUX_tipo | S1: AUX_Responsable
A2: 45868 | B2: CMP-002 | C2: Email | D2: México | E2: Desktop | F2: 129041 | G2: 9255 | H2: 1081 | I2: 4728.14 | J2: 195401.22 | K2: 926 | L2: Adquisición | M2: Carlos Ruiz | N2: =TRIM(PROPER(Tabla_auditoría[[#This Row],[ID_Campaña]])) -> Cmp-002 | O2: =TRIM(PROPER(Tabla_auditoría[[#This Row],[Canal]])) -> Email | P2: =TRIM(PROPER(Tabla_auditoría[[#This Row],[País]])) -> México | Q2: =TRIM(PROPER(Tabla_auditoría[[#This Row],[Dispositivo]])) -> Desktop | R2: =TRIM(PROPER(Tabla_auditoría[[#This Row],[Tipo_Campaña]])) -> Adquisición | S2: =TRIM(PROPER(Tabla_auditoría[[#This Row],[Responsable]])) -> Carlos Ruiz
A3: 45779 | B3: CMP-009 | C3: Paid Search | D3: Italia | E3: Desktop | F3: 50677 | G3: 4047 | H3: 409 | I3: 6481.73 | J3: 65100.85 | K3: 249 | L3: Retención | M3: Luis Martín | N3: =TRIM(PROPER(Tabla_auditoría[[#This Row],[ID_Campaña]])) -> Cmp-009 | O3: =TRIM(PROPER(Tabla_auditoría[[#This Row],[Canal]])) -> Paid Search | P3: =TRIM(PROPER(Tabla_auditoría[[#This Row],[País]])) -> Italia | Q3: =TRIM(PROPER(Tabla_auditoría[[#This Row],[Dispositivo]])) -> Desktop | R3: =TRIM(PROPER(Tabla_auditoría[[#This Row],[Tipo_Campaña]])) -> Retención | S3: =TRIM(PROPER(Tabla_auditoría[[#This Row],[Responsable]])) -> Luis Martín
A4: 45662 | B4: CMP-009 | C4: Email | D4: Francia | E4: Desktop | F4: 12070 | G4: 959 | H4: 57 | I4: 1465.19 | J4: 7772.79 | K4: 31 | L4: Retención | M4: Laura Pérez | N4: =TRIM(PROPER(Tabla_auditoría[[#This Row],[ID_Campaña]])) -> Cmp-009 | O4: =TRIM(PROPER(Tabla_auditoría[[#This Row],[Canal]])) -> Email | P4: =TRIM(PROPER(Tabla_auditoría[[#This Row],[País]])) -> Francia | Q4: =TRIM(PROPER(Tabla_auditoría[[#This Row],[Dispositivo]])) -> Desktop | R4: =TRIM(PROPER(Tabla_auditoría[[#This Row],[Tipo_Campaña]])) -> Retención | S4: =TRIM(PROPER(Tabla_auditoría[[#This Row],[Responsable]])) -> Laura Pérez | U4: Número de registros | V4: =COUNTA(Tabla_auditoría[Fecha]) -> 2535
A5: 45815 | B5: CMP-002 | C5: Affiliate | D5: España | E5: Mobile | F5: 114121 | G5: 890 | H5: 114 | I5: 1196.8 | J5: 24221.44 | K5: 52 | L5: Adquisición | M5: Luis Martín | N5: =TRIM(PROPER(Tabla_auditoría[[#This Row],[ID_Campaña]])) -> Cmp-002 | O5: =TRIM(PROPER(Tabla_auditoría[[#This Row],[Canal]])) -> Affiliate | P5: =TRIM(PROPER(Tabla_auditoría[[#This Row],[País]])) -> España | Q5: =TRIM(PROPER(Tabla_auditoría[[#This Row],[Dispositivo]])) -> Mobile | R5: =TRIM(PROPER(Tabla_auditoría[[#This Row],[Tipo_Campaña]])) -> Adquisición | S5: =TRIM(PROPER(Tabla_auditoría[[#This Row],[Responsable]])) -> Luis Martín
A6: 45916 | B6: CMP-026 | C6: Paid Search | D6: Portugal | E6: Desktop | F6: 123994 | G6: 5563 | H6: 308 | I6: 1315.48 | J6: 47341.08 | K6: 254 | L6: Adquisición | M6: Luis Martín | N6: =TRIM(PROPER(Tabla_auditoría[[#This Row],[ID_Campaña]])) -> Cmp-026 | O6: =TRIM(PROPER(Tabla_auditoría[[#This Row],[Canal]])) -> Paid Search | P6: =TRIM(PROPER(Tabla_auditoría[[#This Row],[País]])) -> Portugal | Q6: =TRIM(PROPER(Tabla_auditoría[[#This Row],[Dispositivo]])) -> Desktop | R6: =TRIM(PROPER(Tabla_auditoría[[#This Row],[Tipo_Campaña]])) -> Adquisición | S6: =TRIM(PROPER(Tabla_auditoría[[#This Row],[Responsable]])) -> Luis Martín | U6: Tabla blancos
A7: 45934 | B7: CMP-022 | C7: Paid Social | D7: Portugal | E7: Tablet | F7: 170534 | G7: 7543 | H7: 96 | I7: 10662.79 | J7: 15691.35 | K7: 51 | L7: Adquisición | M7: Carlos Ruiz | N7: =TRIM(PROPER(Tabla_auditoría[[#This Row],[ID_Campaña]])) -> Cmp-022 | O7: =TRIM(PROPER(Tabla_auditoría[[#This Row],[Canal]])) -> Paid Social | P7: =TRIM(PROPER(Tabla_auditoría[[#This Row],[País]])) -> Portugal | Q7: =TRIM(PROPER(Tabla_auditoría[[#This Row],[Dispositivo]])) -> Tablet | R7: =TRIM(PROPER(Tabla_auditoría[[#This Row],[Tipo_Campaña]])) -> Adquisición | S7: =TRIM(PROPER(Tabla_auditoría[[#This Row],[Responsable]])) -> Carlos Ruiz | U7: Canal | V7: =COUNTBLANK(Tabla_auditoría[Canal]) -> 20
A8: 45828 | B8: CMP-015 | C8: Email | D8: Francia | E8: Tablet | F8: 84579 | G8: 3855 | H8: 121 | I8: 7967.14 | J8: 12733.03 | K8: 58 | L8: Reconocimiento | M8: Marta López | N8: =TRIM(PROPER(Tabla_auditoría[[#This Row],[ID_Campaña]])) -> Cmp-015 | O8: =TRIM(PROPER(Tabla_auditoría[[#This Row],[Canal]])) -> Email | P8: =TRIM(PROPER(Tabla_auditoría[[#This Row],[País]])) -> Francia | Q8: =TRIM(PROPER(Tabla_auditoría[[#This Row],[Dispositivo]])) -> Tablet | R8: =TRIM(PROPER(Tabla_auditoría[[#This Row],[Tipo_Campaña]])) -> Reconocimiento | S8: =TRIM(PROPER(Tabla_auditoría[[#This Row],[Responsable]])) -> Marta López | U8: País | V8: =COUNTBLANK(Tabla_auditoría[País]) -> 16
A9: 45941 | B9: CMP-004 | C9: Affiliate | D9: Portugal | E9: Mobile | F9: 125454 | G9: 7459 | H9: 507 | I9: 14866.14 | J9: 74384.02 | K9: 356 | L9: Conversión | M9: Laura Pérez | N9: =TRIM(PROPER(Tabla_auditoría[[#This Row],[ID_Campaña]])) -> Cmp-004 | O9: =TRIM(PROPER(Tabla_auditoría[[#This Row],[Canal]])) -> Affiliate | P9: =TRIM(PROPER(Tabla_auditoría[[#This Row],[País]])) -> Portugal | Q9: =TRIM(PROPER(Tabla_auditoría[[#This Row],[Dispositivo]])) -> Mobile | R9: =TRIM(PROPER(Tabla_auditoría[[#This Row],[Tipo_Campaña]])) -> Conversión | S9: =TRIM(PROPER(Tabla_auditoría[[#This Row],[Responsable]])) -> Laura Pérez | U9: Gasto | V9: =COUNTBLANK(Tabla_auditoría[Gasto_EUR]) -> 8
A10: 45908 | B10: CMP-017 | C10: Paid Search | D10: Portugal | E10: Desktop | F10: 147026 | G10: 2076 | H10: 174 | I10: 574.55 | J10: 13381.79 | K10: 125 | L10: Conversión | M10: Luis Martín | N10: =TRIM(PROPER(Tabla_auditoría[[#This Row],[ID_Campaña]])) -> Cmp-017 | O10: =TRIM(PROPER(Tabla_auditoría[[#This Row],[Canal]])) -> Paid Search | P10: =TRIM(PROPER(Tabla_auditoría[[#This Row],[País]])) -> Portugal | Q10: =TRIM(PROPER(Tabla_auditoría[[#This Row],[Dispositivo]])) -> Desktop | R10: =TRIM(PROPER(Tabla_auditoría[[#This Row],[Tipo_Campaña]])) -> Conversión | S10: =TRIM(PROPER(Tabla_auditoría[[#This Row],[Responsable]])) -> Luis Martín | U10: Responsable | V10: =COUNTBLANK(Tabla_auditoría[Responsable]) -> 18
A11: 45974 | B11: CMP-002 | C11: Display | D11: Francia | E11: Mobile | F11: 8375 | G11: 469 | H11: 33 | I11: 672.99 | J11: 5104.23 | K11: 18 | L11: Conversión | M11: Marta López | N11: =TRIM(PROPER(Tabla_auditoría[[#This Row],[ID_Campaña]])) -> Cmp-002 | O11: =TRIM(PROPER(Tabla_auditoría[[#This Row],[Canal]])) -> Display | P11: =TRIM(PROPER(Tabla_auditoría[[#This Row],[País]])) -> Francia | Q11: =TRIM(PROPER(Tabla_auditoría[[#This Row],[Dispositivo]])) -> Mobile | R11: =TRIM(PROPER(Tabla_auditoría[[#This Row],[Tipo_Campaña]])) -> Conversión | S11: =TRIM(PROPER(Tabla_auditoría[[#This Row],[Responsable]])) -> Marta López | U11: Total | V11: =SUM(V7:V10) -> 62
A12: 45838 | B12: CMP-025 | C12: Organic Social | D12: España | E12: Desktop | F12: 169640 | G12: 13188 | H12: 1573 | I12: 3188.1 | J12: 158029.53 | K12: 1309 | L12: Retención | M12: Luis Martín | N12: =TRIM(PROPER(Tabla_auditoría[[#This Row],[ID_Campaña]])) -> Cmp-025 | O12: =TRIM(PROPER(Tabla_auditoría[[#This Row],[Canal]])) -> Organic Social | P12: =TRIM(PROPER(Tabla_auditoría[[#This Row],[País]])) -> España | Q12: =TRIM(PROPER(Tabla_auditoría[[#This Row],[Dispositivo]])) -> Desktop | R12: =TRIM(PROPER(Tabla_auditoría[[#This Row],[Tipo_Campaña]])) -> Retención | S12: =TRIM(PROPER(Tabla_auditoría[[#This Row],[Responsable]])) -> Luis Martín
A13: 45697 | B13: CMP-006 | C13: Email | D13: España | E13: Desktop | F13: 1815 | G13: 46 | H13: 1 | I13: 54.04 | J13: 192.07 | K13: 0 | L13: Conversión | M13: Marta López | N13: =TRIM(PROPER(Tabla_auditoría[[#This Row],[ID_Campaña]])) -> Cmp-006 | O13: =TRIM(PROPER(Tabla_auditoría[[#This Row],[Canal]])) -> Email | P13: =TRIM(PROPER(Tabla_auditoría[[#This Row],[País]])) -> España | Q13: =TRIM(PROPER(Tabla_auditoría[[#This Row],[Dispositivo]])) -> Desktop | R13: =TRIM(PROPER(Tabla_auditoría[[#This Row],[Tipo_Campaña]])) -> Conversión | S13: =TRIM(PROPER(Tabla_auditoría[[#This Row],[Responsable]])) -> Marta López
A14: 45992 | B14: CMP-011 | C14: Paid Social | D14: España | E14: Mobile | F14: 58400 | G14: 2796 | H14: 80 | I14: 361.39 | J14: 8867.74 | K14: 71 | L14: Reconocimiento | M14: Ana García | N14: =TRIM(PROPER(Tabla_auditoría[[#This Row],[ID_Campaña]])) -> Cmp-011 | O14: =TRIM(PROPER(Tabla_auditoría[[#This Row],[Canal]])) -> Paid Social | P14: =TRIM(PROPER(Tabla_auditoría[[#This Row],[País]])) -> España | Q14: =TRIM(PROPER(Tabla_auditoría[[#This Row],[Dispositivo]])) -> Mobile | R14: =TRIM(PROPER(Tabla_auditoría[[#This Row],[Tipo_Campaña]])) -> Reconocimiento | S14: =TRIM(PROPER(Tabla_auditoría[[#This Row],[Responsable]])) -> Ana García
A15: 45688 | B15: CMP-018 | C15: display | D15: México | E15: Desktop | F15: 95164 | G15: 467 | H15: 54 | I15: 899.8 | J15: 8314.82 | K15: 33 | L15: Retención | M15: Carlos Ruiz | N15: =TRIM(PROPER(Tabla_auditoría[[#This Row],[ID_Campaña]])) -> Cmp-018 | O15: =TRIM(PROPER(Tabla_auditoría[[#This Row],[Canal]])) -> Display | P15: =TRIM(PROPER(Tabla_auditoría[[#This Row],[País]])) -> México | Q15: =TRIM(PROPER(Tabla_auditoría[[#This Row],[Dispositivo]])) -> Desktop | R15: =TRIM(PROPER(Tabla_auditoría[[#This Row],[Tipo_Campaña]])) -> Retención | S15: =TRIM(PROPER(Tabla_auditoría[[#This Row],[Responsable]])) -> Carlos Ruiz
A16: 45938 | B16: CMP-004 | C16: Email | D16: España | E16: Desktop | F16: 163224 | G16: 892 | H16: 116 | I16: 645.97 | J16: 13245.61 | K16: 70 | L16: Reconocimiento | M16: Ana García | N16: =TRIM(PROPER(Tabla_auditoría[[#This Row],[ID_Campaña]])) -> Cmp-004 | O16: =TRIM(PROPER(Tabla_auditoría[[#This Row],[Canal]])) -> Email | P16: =TRIM(PROPER(Tabla_auditoría[[#This Row],[País]])) -> España | Q16: =TRIM(PROPER(Tabla_auditoría[[#This Row],[Dispositivo]])) -> Desktop | R16: =TRIM(PROPER(Tabla_auditoría[[#This Row],[Tipo_Campaña]])) -> Reconocimiento | S16: =TRIM(PROPER(Tabla_auditoría[[#This Row],[Responsable]])) -> Ana García
A17: 45780 | B17: CMP-007 | C17: Affiliate | D17: Francia | E17: Tablet | F17: 44509 | G17: 1756 | H17: 45 | I17: 2433.77 | J17: 1487.74 | K17: 24 | L17: Conversión | M17: Ana García | N17: =TRIM(PROPER(Tabla_auditoría[[#This Row],[ID_Campaña]])) -> Cmp-007 | O17: =TRIM(PROPER(Tabla_auditoría[[#This Row],[Canal]])) -> Affiliate | P17: =TRIM(PROPER(Tabla_auditoría[[#This Row],[País]])) -> Francia | Q17: =TRIM(PROPER(Tabla_auditoría[[#This Row],[Dispositivo]])) -> Tablet | R17: =TRIM(PROPER(Tabla_auditoría[[#This Row],[Tipo_Campaña]])) -> Conversión | S17: =TRIM(PROPER(Tabla_auditoría[[#This Row],[Responsable]])) -> Ana García
A18: 45799 | B18: CMP-018 | C18: Email | D18: España | E18: Tablet | F18: 49699 | G18: 549 | H18: 14 | I18: 407.19 | J18: 2598.86 | K18: 12 | L18: Conversión | M18: Marta López | N18: =TRIM(PROPER(Tabla_auditoría[[#This Row],[ID_Campaña]])) -> Cmp-018 | O18: =TRIM(PROPER(Tabla_auditoría[[#This Row],[Canal]])) -> Email | P18: =TRIM(PROPER(Tabla_auditoría[[#This Row],[País]])) -> España | Q18: =TRIM(PROPER(Tabla_auditoría[[#This Row],[Dispositivo]])) -> Tablet | R18: =TRIM(PROPER(Tabla_auditoría[[#This Row],[Tipo_Campaña]])) -> Conversión | S18: =TRIM(PROPER(Tabla_auditoría[[#This Row],[Responsable]])) -> Marta López
A19: 45738 | B19: CMP-011 | C19: Affiliate | D19: España | E19: Mobile | F19: 79946 | G19: 6644 | H19: 165 | I19: 12172.18 | J19: 3700.53 | K19: 97 | L19: Retención | M19: Luis Martín | N19: =TRIM(PROPER(Tabla_auditoría[[#This Row],[ID_Campaña]])) -> Cmp-011 | O19: =TRIM(PROPER(Tabla_auditoría[[#This Row],[Canal]])) -> Affiliate | P19: =TRIM(PROPER(Tabla_auditoría[[#This Row],[País]])) -> España | Q19: =TRIM(PROPER(Tabla_auditoría[[#This Row],[Dispositivo]])) -> Mobile | R19: =TRIM(PROPER(Tabla_auditoría[[#This Row],[Tipo_Campaña]])) -> Retención | S19: =TRIM(PROPER(Tabla_auditoría[[#This Row],[Responsable]])) -> Luis Martín
A20: 45765 | B20: CMP-022 | C20: Display | D20: México | E20: Mobile | F20: 90643 | G20: 6251 | H20: 607 | I20: 1069.28 | J20: 85223.12 | K20: 473 | L20: Adquisición | M20: Ana García | N20: =TRIM(PROPER(Tabla_auditoría[[#This Row],[ID_Campaña]])) -> Cmp-022 | O20: =TRIM(PROPER(Tabla_auditoría[[#This Row],[Canal]])) -> Display | P20: =TRIM(PROPER(Tabla_auditoría[[#This Row],[País]])) -> México | Q20: =TRIM(PROPER(Tabla_auditoría[[#This Row],[Dispositivo]])) -> Mobile | R20: =TRIM(PROPER(Tabla_auditoría[[#This Row],[Tipo_Campaña]])) -> Adquisición | S20: =TRIM(PROPER(Tabla_auditoría[[#This Row],[Responsable]])) -> Ana García
A21: 45973 | B21: CMP-008 | C21: Display | D21: España | E21: Mobile | F21: 78294 | G21: 5439 | H21: 617 | I21: 1504.93 | J21: 130219.67 | K21: 538 | L21: Conversión | M21: Laura Pérez | N21: =TRIM(PROPER(Tabla_auditoría[[#This Row],[ID_Campaña]])) -> Cmp-008 | O21: =TRIM(PROPER(Tabla_auditoría[[#This Row],[Canal]])) -> Display | P21: =TRIM(PROPER(Tabla_auditoría[[#This Row],[País]])) -> España | Q21: =TRIM(PROPER(Tabla_auditoría[[#This Row],[Dispositivo]])) -> Mobile | R21: =TRIM(PROPER(Tabla_auditoría[[#This Row],[Tipo_Campaña]])) -> Conversión | S21: =TRIM(PROPER(Tabla_auditoría[[#This Row],[Responsable]])) -> Laura Pérez
A22: 46009 | B22: CMP-028 | C22: Paid Search | D22: Francia | E22: Desktop | F22: 4759 | G22: 234 | H22: 22 | I22: 333.25 | J22: 2425.61 | K22: 13 | L22: Retención | M22: Ana García | N22: =TRIM(PROPER(Tabla_auditoría[[#This Row],[ID_Campaña]])) -> Cmp-028 | O22: =TRIM(PROPER(Tabla_auditoría[[#This Row],[Canal]])) -> Paid Search | P22: =TRIM(PROPER(Tabla_auditoría[[#This Row],[País]])) -> Francia | Q22: =TRIM(PROPER(Tabla_auditoría[[#This Row],[Dispositivo]])) -> Desktop | R22: =TRIM(PROPER(Tabla_auditoría[[#This Row],[Tipo_Campaña]])) -> Retención | S22: =TRIM(PROPER(Tabla_auditoría[[#This Row],[Responsable]])) -> Ana García
A23: 45791 | B23: CMP-012 | C23: Organic Social | D23: Francia | E23: Mobile | F23: 7310 | G23: 569 | H23: 77 | I23: 65.92 | J23: 3364.24 | K23: 59 | L23: Reconocimiento | M23: Luis Martín | N23: =TRIM(PROPER(Tabla_auditoría[[#This Row],[ID_Campaña]])) -> Cmp-012 | O23: =TRIM(PROPER(Tabla_auditoría[[#This Row],[Canal]])) -> Organic Social | P23: =TRIM(PROPER(Tabla_auditoría[[#This Row],[País]])) -> Francia | Q23: =TRIM(PROPER(Tabla_auditoría[[#This Row],[Dispositivo]])) -> Mobile | R23: =TRIM(PROPER(Tabla_auditoría[[#This Row],[Tipo_Campaña]])) -> Reconocimiento | S23: =TRIM(PROPER(Tabla_auditoría[[#This Row],[Responsable]])) -> Luis Martín
... A35: 45921 | B35: CMP-010 | C35: paid social | D35: Francia | E35: Mobile | F35: 78190 | G35: 387 | H35: 31 | I35: 203.63 | J35: 6507.47 | K35: 16 | L35: Retención | M35: Marta López | N35: =TRIM(PROPER(Tabla_auditoría[[#This Row],[ID_Campaña]])) -> Cmp-010 | O35: =TRIM(PROPER(Tabla_auditoría[[#This Row],[Canal]])) -> Paid Social | P35: =TRIM(PROPER(Tabla_auditoría[[#This Row],[País]])) -> Francia | Q35: =TRIM(PROPER(Tabla_auditoría[[#This Row],[Dispositivo]])) -> Mobile | R35: =TRIM(PROPER(Tabla_auditoría[[#This Row],[Tipo_Campaña]])) -> Retención | S35: =TRIM(PROPER(Tabla_auditoría[[#This Row],[Responsable]])) -> Marta López
A36: 45755 | B36: CMP-010 | D36: México | E36: DESKTOP | F36: 63702 | G36: 5675 | H36: 708 | I36: 4115.09 | J36: 107477.07 | K36: 459 | L36: Reconocimiento | M36: Ana García | N36: =TRIM(PROPER(Tabla_auditoría[[#This Row],[ID_Campaña]])) -> Cmp-010 | O36: =TRIM(PROPER(Tabla_auditoría[[#This Row],[Canal]])) | P36: =TRIM(PROPER(Tabla_auditoría[[#This Row],[País]])) -> México | Q36: =TRIM(PROPER(Tabla_auditoría[[#This Row],[Dispositivo]])) -> Desktop | R36: =TRIM(PROPER(Tabla_auditoría[[#This Row],[Tipo_Campaña]])) -> Reconocimiento | S36: =TRIM(PROPER(Tabla_auditoría[[#This Row],[Responsable]])) -> Ana García
A37: 45781 | B37: CMP-027 | C37: Display | D37: Francia | E37: Mobile | F37: 62593 | G37: 3168 | H37: 202 | I37: 1472.4 | J37: 11607.45 | K37: 102 | L37: Adquisición | M37: Carlos Ruiz | N37: =TRIM(PROPER(Tabla_auditoría[[#This Row],[ID_Campaña]])) -> Cmp-027 | O37: =TRIM(PROPER(Tabla_auditoría[[#This Row],[Canal]])) -> Display | P37: =TRIM(PROPER(Tabla_auditoría[[#This Row],[País]])) -> Francia | Q37: =TRIM(PROPER(Tabla_auditoría[[#This Row],[Dispositivo]])) -> Mobile | R37: =TRIM(PROPER(Tabla_auditoría[[#This Row],[Tipo_Campaña]])) -> Adquisición | S37: =TRIM(PROPER(Tabla_auditoría[[#This Row],[Responsable]])) -> Carlos Ruiz
A38: 45680 | B38: CMP-002 | C38: Email | D38: México | E38: Desktop | F38: 91161 | G38: 4430 | H38: 265 | I38: 5935.04 | J38: 35663.11 | K38: 186 | L38: Conversión | M38: Carlos Ruiz | N38: =TRIM(PROPER(Tabla_auditoría[[#This Row],[ID_Campaña]])) -> Cmp-002 | O38: =TRIM(PROPER(Tabla_auditoría[[#This Row],[Canal]])) -> Email | P38: =TRIM(PROPER(Tabla_auditoría[[#This Row],[País]])) -> México | Q38: =TRIM(PROPER(Tabla_auditoría[[#This Row],[Dispositivo]])) -> Desktop | R38: =TRIM(PROPER(Tabla_auditoría[[#This Row],[Tipo_Campaña]])) -> Conversión | S38: =TRIM(PROPER(Tabla_auditoría[[#This Row],[Responsable]])) -> Carlos Ruiz
A39: 45720 | B39: CMP-012 | C39: Display | D39: España | E39: MOBILE | F39: 16564 | G39: 169 | H39: 4 | I39: 152.83 | J39: 769.28 | K39: 2 | L39: Conversión | M39: Ana García | N39: =TRIM(PROPER(Tabla_auditoría[[#This Row],[ID_Campaña]])) -> Cmp-012 | O39: =TRIM(PROPER(Tabla_auditoría[[#This Row],[Canal]])) -> Display | P39: =TRIM(PROPER(Tabla_auditoría[[#This Row],[País]])) -> España | Q39: =TRIM(PROPER(Tabla_auditoría[[#This Row],[Dispositivo]])) -> Mobile | R39: =TRIM(PROPER(Tabla_auditoría[[#This Row],[Tipo_Campaña]])) -> Conversión | S39: =TRIM(PROPER(Tabla_auditoría[[#This Row],[Responsable]])) -> Ana García
A40: 45722 | B40: CMP-019 | C40: Paid Search | D40: Francia | E40: Desktop | F40: 65604 | G40: 2826 | H40: 147 | I40: 370.78 | J40: 8547.51 | K40: 112 | L40: Retención | M40: Ana García | N40: =TRIM(PROPER(Tabla_auditoría[[#This Row],[ID_Campaña]])) -> Cmp-019 | O40: =TRIM(PROPER(Tabla_auditoría[[#This Row],[Canal]])) -> Paid Search | P40: =TRIM(PROPER(Tabla_auditoría[[#This Row],[País]])) -> Francia | Q40: =TRIM(PROPER(Tabla_auditoría[[#This Row],[Dispositivo]])) -> Desktop | R40: =TRIM(PROPER(Tabla_auditoría[[#This Row],[Tipo_Campaña]])) -> Retención | S40: =TRIM(PROPER(Tabla_auditoría[[#This Row],[Responsable]])) -> Ana García
A41: 45775 | B41: CMP-002 | C41: Affiliate | D41: Italia | E41: Mobile | F41: 84707 | G41: 512 | H41: 33 | I41: 940.78 | J41: 6912.23 | K41: 17 | L41: Retención | M41: Luis Martín | N41: =TRIM(PROPER(Tabla_auditoría[[#This Row],[ID_Campaña]])) -> Cmp-002 | O41: =TRIM(PROPER(Tabla_auditoría[[#This Row],[Canal]])) -> Affiliate | P41: =TRIM(PROPER(Tabla_auditoría[[#This Row],[País]])) -> Italia | Q41: =TRIM(PROPER(Tabla_auditoría[[#This Row],[Dispositivo]])) -> Mobile | R41: =TRIM(PROPER(Tabla_auditoría[[#This Row],[Tipo_Campaña]])) -> Retención | S41: =TRIM(PROPER(Tabla_auditoría[[#This Row],[Responsable]])) -> Luis Martín
A42: 45748 | B42: CMP-008 | C42: organic social | D42: México | E42: Desktop | F42: 125379 | G42: 2816 | H42: 211 | I42: 2108.8 | J42: 14718.61 | K42: 168 | L42: Conversión | M42: Carlos Ruiz | N42: =TRIM(PROPER(Tabla_auditoría[[#This Row],[ID_Campaña]])) -> Cmp-008 | O42: =TRIM(PROPER(Tabla_auditoría[[#This Row],[Canal]])) -> Organic Social | P42: =TRIM(PROPER(Tabla_auditoría[[#This Row],[País]])) -> México | Q42: =TRIM(PROPER(Tabla_auditoría[[#This Row],[Dispositivo]])) -> Desktop | R42: =TRIM(PROPER(Tabla_auditoría[[#This Row],[Tipo_Campaña]])) -> Conversión | S42: =TRIM(PROPER(Tabla_auditoría[[#This Row],[Responsable]])) -> Carlos Ruiz
A43: 45788 | B43: CMP-030 | C43: Affiliate | D43: Italia | E43: Mobile | F43: 75503 | G43: 3617 | H43: 24 | I43: 3324.61 | J43: 462.18 | K43: 13 | L43: Conversión | M43: Ana García | N43: =TRIM(PROPER(Tabla_auditoría[[#This Row],[ID_Campaña]])) -> Cmp-030 | O43: =TRIM(PROPER(Tabla_auditoría[[#This Row],[Canal]])) -> Affiliate | P43: =TRIM(PROPER(Tabla_auditoría[[#This Row],[País]])) -> Italia | Q43: =TRIM(PROPER(Tabla_auditoría[[#This Row],[Dispositivo]])) -> Mobile | R43: =TRIM(PROPER(Tabla_auditoría[[#This Row],[Tipo_Campaña]])) -> Conversión | S43: =TRIM(PROPER(Tabla_auditoría[[#This Row],[Responsable]])) -> Ana García
A44: 45911 | B44: CMP-014 | C44: Paid Search | D44: Francia | E44: Desktop | F44: 177363 | G44: 7732 | H44: 999 | I44: 9531.17 | J44: 71611.15 | K44: 470 | L44: Conversión | M44: Marta López | N44: =TRIM(PROPER(Tabla_auditoría[[#This Row],[ID_Campaña]])) -> Cmp-014 | O44: =TRIM(PROPER(Tabla_auditoría[[#This Row],[Canal]])) -> Paid Search | P44: =TRIM(PROPER(Tabla_auditoría[[#This Row],[País]])) -> Francia | Q44: =TRIM(PROPER(Tabla_auditoría[[#This Row],[Dispositivo]])) -> Desktop | R44: =TRIM(PROPER(Tabla_auditoría[[#This Row],[Tipo_Campaña]])) -> Conversión | S44: =TRIM(PROPER(Tabla_auditoría[[#This Row],[Responsable]])) -> Marta López
A45: 45784 | B45: CMP-026 | C45: Email | D45: España | E45: Mobile | F45: 160559 | G45: 8096 | H45: 866 | I45: 14024.15 | J45: 165614.97 | K45: 406 | L45: Retención | M45: Luis Martín | N45: =TRIM(PROPER(Tabla_auditoría[[#This Row],[ID_Campaña]])) -> Cmp-026 | O45: =TRIM(PROPER(Tabla_auditoría[[#This Row],[Canal]])) -> Email | P45: =TRIM(PROPER(Tabla_auditoría[[#This Row],[País]])) -> España | Q45: =TRIM(PROPER(Tabla_auditoría[[#This Row],[Dispositivo]])) -> Mobile | R45: =TRIM(PROPER(Tabla_auditoría[[#This Row],[Tipo_Campaña]])) -> Retención | S45: =TRIM(PROPER(Tabla_auditoría[[#This Row],[Responsable]])) -> Luis Martín
A46: 46010 | B46: CMP-011 | C46: Organic Social | D46: Italia | E46: Tablet | F46: 134062 | G46: 11816 | H46: 1010 | I46: 23456.15 | J46: 139056.15 | K46: 867 | L46: Retención | M46: Carlos Ruiz | N46: =TRIM(PROPER(Tabla_auditoría[[#This Row],[ID_Campaña]])) -> Cmp-011 | O46: =TRIM(PROPER(Tabla_auditoría[[#This Row],[Canal]])) -> Organic Social | P46: =TRIM(PROPER(Tabla_auditoría[[#This Row],[País]])) -> Italia | Q46: =TRIM(PROPER(Tabla_auditoría[[#This Row],[Dispositivo]])) -> Tablet | R46: =TRIM(PROPER(Tabla_auditoría[[#This Row],[Tipo_Campaña]])) -> Retención | S46: =TRIM(PROPER(Tabla_auditoría[[#This Row],[Responsable]])) -> Carlos Ruiz
A47: 45662 | B47: CMP-014 | C47: Paid Social | D47: Portugal | E47: Mobile | F47: 80985 | G47: 3516 | H47: 69 | I47: 1147.83 | J47: 7612.07 | K47: 57 | L47: Reconocimiento | M47: Carlos Ruiz | N47: =TRIM(PROPER(Tabla_auditoría[[#This Row],[ID_Campaña]])) -> Cmp-014 | O47: =TRIM(PROPER(Tabla_auditoría[[#This Row],[Canal]])) -> Paid Social | P47: =TRIM(PROPER(Tabla_auditoría[[#This Row],[País]])) -> Portugal | Q47: =TRIM(PROPER(Tabla_auditoría[[#This Row],[Dispositivo]])) -> Mobile | R47: =TRIM(PROPER(Tabla_auditoría[[#This Row],[Tipo_Campaña]])) -> Reconocimiento | S47: =TRIM(PROPER(Tabla_auditoría[[#This Row],[Responsable]])) -> Carlos Ruiz
A48: 45860 | B48: CMP-023 | C48: Paid Search | D48: México | E48: Tablet | F48: 172110 | G48: 4863 | H48: 151 | I48: 4544.82 | J48: 12852.56 | K48: 78 | L48: Conversión | M48: Marta López | N48: =TRIM(PROPER(Tabla_auditoría[[#This Row],[ID_Campaña]])) -> Cmp-023 | O48: =TRIM(PROPER(Tabla_auditoría[[#This Row],[Canal]])) -> Paid Search | P48: =TRIM(PROPER(Tabla_auditoría[[#This Row],[País]])) -> México | Q48: =TRIM(PROPER(Tabla_auditoría[[#This Row],[Dispositivo]])) -> Tablet | R48: =TRIM(PROPER(Tabla_auditoría[[#This Row],[Tipo_Campaña]])) -> Conversión | S48: =TRIM(PROPER(Tabla_auditoría[[#This Row],[Responsable]])) -> Marta López
... A92: 45834 | B92: CMP-020 | C92: Paid Social | D92: Italia | E92: Mobile | F92: 168186 | G92: 12846 | H92: 248 | I92: 11843.19 | J92: 16511.03 | K92: 193 | L92: Conversión | M92: Laura Pérez | N92: =TRIM(PROPER(Tabla_auditoría[[#This Row],[ID_Campaña]])) -> Cmp-020 | O92: =TRIM(PROPER(Tabla_auditoría[[#This Row],[Canal]])) -> Paid Social | P92: =TRIM(PROPER(Tabla_auditoría[[#This Row],[País]])) -> Italia | Q92: =TRIM(PROPER(Tabla_auditoría[[#This Row],[Dispositivo]])) -> Mobile | R92: =TRIM(PROPER(Tabla_auditoría[[#This Row],[Tipo_Campaña]])) -> Conversión | S92: =TRIM(PROPER(Tabla_auditoría[[#This Row],[Responsable]])) -> Laura Pérez
A93: 45719 | B93: CMP-024 | C93: Organic Social | D93: Francia | E93: Desktop | F93: 125337 | G93: 4913 | H93: 247 | J93: 19111.59 | K93: 173 | L93: Retención | M93: Ana García | N93: =TRIM(PROPER(Tabla_auditoría[[#This Row],[ID_Campaña]])) -> Cmp-024 | O93: =TRIM(PROPER(Tabla_auditoría[[#This Row],[Canal]])) -> Organic Social | P93: =TRIM(PROPER(Tabla_auditoría[[#This Row],[País]])) -> Francia | Q93: =TRIM(PROPER(Tabla_auditoría[[#This Row],[Dispositivo]])) -> Desktop | R93: =TRIM(PROPER(Tabla_auditoría[[#This Row],[Tipo_Campaña]])) -> Retención | S93: =TRIM(PROPER(Tabla_auditoría[[#This Row],[Responsable]])) -> Ana García
A94: 45770 | B94: CMP-008 | C94: Affiliate | D94: Portugal | E94: Mobile | F94: 156107 | G94: 10929 | H94: 151 | I94: 14137.01 | J94: 25165.32 | K94: 106 | L94: Retención | M94: Carlos Ruiz | N94: =TRIM(PROPER(Tabla_auditoría[[#This Row],[ID_Campaña]])) -> Cmp-008 | O94: =TRIM(PROPER(Tabla_auditoría[[#This Row],[Canal]])) -> Affiliate | P94: =TRIM(PROPER(Tabla_auditoría[[#This Row],[País]])) -> Portugal | Q94: =TRIM(PROPER(Tabla_auditoría[[#This Row],[Dispositivo]])) -> Mobile | R94: =TRIM(PROPER(Tabla_auditoría[[#This Row],[Tipo_Campaña]])) -> Retención | S94: =TRIM(PROPER(Tabla_auditoría[[#This Row],[Responsable]])) -> Carlos Ruiz
...

Sheet Control de datos
A1: Fecha | B1: ID_Campaña | C1: Canal | D1: País | E1: Dispositivo | F1: Impresiones | G1: Clics | H1: Conversiones | I1: Gasto_EUR | J1: Ingresos_EUR | K1: Nuevos_Clientes | L1: Tipo_Campaña | M1: Responsable | N1: Control_duplicados | O1: Duplicados | P1: Control_gasto | Q1: Control_conversiones | R1: Control_nuevos_clientes
A2: 45868 | B2: Cmp-002 | C2: Email | D2: México | E2: Desktop | F2: 129041 | G2: 9255 | H2: 1081 | I2: 4728.14 | J2: 195401.22 | K2: 926 | L2: Adquisición | M2: Carlos Ruiz | N2: =COUNTIFS($A$2:$A$2536,A2,$B$2:$B$2536,B2,$C$2:$C$2536,C2,$D$2:$D$2536,D2,$E$2:$E$2536,E2,$F$2:$F$2536,F2,$G$2:$G$2536,G2,$H$2:$H$2536,H2,$I$2:$I$2536,I2,$J$2:$J$2536,J2,$K$2:$K$2536,K2,$L$2:$L$2536,L2,$M$2:$M$2536,M2) -> 1 | O2: =IF(Tabla_control[[#This Row],[Control_duplicados]]>1,"Duplicado","Unico") -> Unico | P2: =IF(OR(I2="",I2<0),"ERROR","OK") -> OK | Q2: =IF(H2>F2,"ERROR","OK") -> OK | R2: =IF(K2>H2,"ERROR","OK") -> OK
A3: 45779 | B3: Cmp-009 | C3: Paid Search | D3: Italia | E3: Desktop | F3: 50677 | G3: 4047 | H3: 409 | I3: 6481.73 | J3: 65100.85 | K3: 249 | L3: Retención | M3: Luis Martín | N3: =COUNTIFS($A$2:$A$2536,A3,$B$2:$B$2536,B3,$C$2:$C$2536,C3,$D$2:$D$2536,D3,$E$2:$E$2536,E3,$F$2:$F$2536,F3,$G$2:$G$2536,G3,$H$2:$H$2536,H3,$I$2:$I$2536,I3,$J$2:$J$2536,J3,$K$2:$K$2536,K3,$L$2:$L$2536,L3,$M$2:$M$2536,M3) -> 2 | O3: =IF(Tabla_control[[#This Row],[Control_duplicados]]>1,"Duplicado","Unico") -> Duplicado | P3: =IF(OR(I3="",I3<0),"ERROR","OK") -> OK | Q3: =IF(H3>F3,"ERROR","OK") -> OK | R3: =IF(K3>H3,"ERROR","OK") -> OK | U3: Tabla control
A4: 45662 | B4: Cmp-009 | C4: Email | D4: Francia | E4: Desktop | F4: 12070 | G4: 959 | H4: 57 | I4: 1465.19 | J4: 7772.79 | K4: 31 | L4: Retención | M4: Laura Pérez | N4: =COUNTIFS($A$2:$A$2536,A4,$B$2:$B$2536,B4,$C$2:$C$2536,C4,$D$2:$D$2536,D4,$E$2:$E$2536,E4,$F$2:$F$2536,F4,$G$2:$G$2536,G4,$H$2:$H$2536,H4,$I$2:$I$2536,I4,$J$2:$J$2536,J4,$K$2:$K$2536,K4,$L$2:$L$2536,L4,$M$2:$M$2536,M4) -> 1 | O4: =IF(Tabla_control[[#This Row],[Control_duplicados]]>1,"Duplicado","Unico") -> Unico | P4: =IF(OR(I4="",I4<0),"ERROR","OK") -> OK | Q4: =IF(H4>F4,"ERROR","OK") -> OK | R4: =IF(K4>H4,"ERROR","OK") -> OK
A5: 45815 | B5: Cmp-002 | C5: Affiliate | D5: España | E5: Mobile | F5: 114121 | G5: 890 | H5: 114 | I5: 1196.8 | J5: 24221.44 | K5: 52 | L5: Adquisición | M5: Luis Martín | N5: =COUNTIFS($A$2:$A$2536,A5,$B$2:$B$2536,B5,$C$2:$C$2536,C5,$D$2:$D$2536,D5,$E$2:$E$2536,E5,$F$2:$F$2536,F5,$G$2:$G$2536,G5,$H$2:$H$2536,H5,$I$2:$I$2536,I5,$J$2:$J$2536,J5,$K$2:$K$2536,K5,$L$2:$L$2536,L5,$M$2:$M$2536,M5) -> 1 | O5: =IF(Tabla_control[[#This Row],[Control_duplicados]]>1,"Duplicado","Unico") -> Unico | P5: =IF(OR(I5="",I5<0),"ERROR","OK") -> OK | Q5: =IF(H5>F5,"ERROR","OK") -> OK | R5: =IF(K5>H5,"ERROR","OK") -> OK | T5: =COUNTIFS(Tabla_control[Duplicados],"Duplicado") -> 70 | U5: Duplicados | V5: =T5/2 -> 35
A6: 45916 | B6: Cmp-026 | C6: Paid Search | D6: Portugal | E6: Desktop | F6: 123994 | G6: 5563 | H6: 308 | I6: 1315.48 | J6: 47341.08 | K6: 254 | L6: Adquisición | M6: Luis Martín | N6: =COUNTIFS($A$2:$A$2536,A6,$B$2:$B$2536,B6,$C$2:$C$2536,C6,$D$2:$D$2536,D6,$E$2:$E$2536,E6,$F$2:$F$2536,F6,$G$2:$G$2536,G6,$H$2:$H$2536,H6,$I$2:$I$2536,I6,$J$2:$J$2536,J6,$K$2:$K$2536,K6,$L$2:$L$2536,L6,$M$2:$M$2536,M6) -> 1 | O6: =IF(Tabla_control[[#This Row],[Control_duplicados]]>1,"Duplicado","Unico") -> Unico | P6: =IF(OR(I6="",I6<0),"ERROR","OK") -> OK | Q6: =IF(H6>F6,"ERROR","OK") -> OK | R6: =IF(K6>H6,"ERROR","OK") -> OK | U6: Control_gasto | V6: =COUNTIF(Tabla_control[Control_gasto],"ERROR") -> 16
A7: 45934 | B7: Cmp-022 | C7: Paid Social | D7: Portugal | E7: Tablet | F7: 170534 | G7: 7543 | H7: 96 | I7: 10662.79 | J7: 15691.35 | K7: 51 | L7: Adquisición | M7: Carlos Ruiz | N7: =COUNTIFS($A$2:$A$2536,A7,$B$2:$B$2536,B7,$C$2:$C$2536,C7,$D$2:$D$2536,D7,$E$2:$E$2536,E7,$F$2:$F$2536,F7,$G$2:$G$2536,G7,$H$2:$H$2536,H7,$I$2:$I$2536,I7,$J$2:$J$2536,J7,$K$2:$K$2536,K7,$L$2:$L$2536,L7,$M$2:$M$2536,M7) -> 1 | O7: =IF(Tabla_control[[#This Row],[Control_duplicados]]>1,"Duplicado","Unico") -> Unico | P7: =IF(OR(I7="",I7<0),"ERROR","OK") -> OK | Q7: =IF(H7>F7,"ERROR","OK") -> OK | R7: =IF(K7>H7,"ERROR","OK") -> OK | U7: Control_conversiones | V7: =COUNTIF(Tabla_control[Control_conversiones],"ERROR") -> 0
A8: 45828 | B8: Cmp-015 | C8: Email | D8: Francia | E8: Tablet | F8: 84579 | G8: 3855 | H8: 121 | I8: 7967.14 | J8: 12733.03 | K8: 58 | L8: Reconocimiento | M8: Marta López | N8: =COUNTIFS($A$2:$A$2536,A8,$B$2:$B$2536,B8,$C$2:$C$2536,C8,$D$2:$D$2536,D8,$E$2:$E$2536,E8,$F$2:$F$2536,F8,$G$2:$G$2536,G8,$H$2:$H$2536,H8,$I$2:$I$2536,I8,$J$2:$J$2536,J8,$K$2:$K$2536,K8,$L$2:$L$2536,L8,$M$2:$M$2536,M8) -> 1 | O8: =IF(Tabla_control[[#This Row],[Control_duplicados]]>1,"Duplicado","Unico") -> Unico | P8: =IF(OR(I8="",I8<0),"ERROR","OK") -> OK | Q8: =IF(H8>F8,"ERROR","OK") -> OK | R8: =IF(K8>H8,"ERROR","OK") -> OK | U8: Control_nuevos_clientes | V8: =COUNTIF(Tabla_control[Control_nuevos_clientes],"ERROR") -> 0
A9: 45941 | B9: Cmp-004 | C9: Affiliate | D9: Portugal | E9: Mobile | F9: 125454 | G9: 7459 | H9: 507 | I9: 14866.14 | J9: 74384.02 | K9: 356 | L9: Conversión | M9: Laura Pérez | N9: =COUNTIFS($A$2:$A$2536,A9,$B$2:$B$2536,B9,$C$2:$C$2536,C9,$D$2:$D$2536,D9,$E$2:$E$2536,E9,$F$2:$F$2536,F9,$G$2:$G$2536,G9,$H$2:$H$2536,H9,$I$2:$I$2536,I9,$J$2:$J$2536,J9,$K$2:$K$2536,K9,$L$2:$L$2536,L9,$M$2:$M$2536,M9) -> 1 | O9: =IF(Tabla_control[[#This Row],[Control_duplicados]]>1,"Duplicado","Unico") -> Unico | P9: =IF(OR(I9="",I9<0),"ERROR","OK") -> OK | Q9: =IF(H9>F9,"ERROR","OK") -> OK | R9: =IF(K9>H9,"ERROR","OK") -> OK | U9: Total | V9: =SUM(V5:V8) -> 51
A10: 45908 | B10: Cmp-017 | C10: Paid Search | D10: Portugal | E10: Desktop | F10: 147026 | G10: 2076 | H10: 174 | I10: 574.55 | J10: 13381.79 | K10: 125 | L10: Conversión | M10: Luis Martín | N10: =COUNTIFS($A$2:$A$2536,A10,$B$2:$B$2536,B10,$C$2:$C$2536,C10,$D$2:$D$2536,D10,$E$2:$E$2536,E10,$F$2:$F$2536,F10,$G$2:$G$2536,G10,$H$2:$H$2536,H10,$I$2:$I$2536,I10,$J$2:$J$2536,J10,$K$2:$K$2536,K10,$L$2:$L$2536,L10,$M$2:$M$2536,M10) -> 1 | O10: =IF(Tabla_control[[#This Row],[Control_duplicados]]>1,"Duplicado","Unico") -> Unico | P10: =IF(OR(I10="",I10<0),"ERROR","OK") -> OK | Q10: =IF(H10>F10,"ERROR","OK") -> OK | R10: =IF(K10>H10,"ERROR","OK") -> OK
A11: 45974 | B11: Cmp-002 | C11: Display | D11: Francia | E11: Mobile | F11: 8375 | G11: 469 | H11: 33 | I11: 672.99 | J11: 5104.23 | K11: 18 | L11: Conversión | M11: Marta López | N11: =COUNTIFS($A$2:$A$2536,A11,$B$2:$B$2536,B11,$C$2:$C$2536,C11,$D$2:$D$2536,D11,$E$2:$E$2536,E11,$F$2:$F$2536,F11,$G$2:$G$2536,G11,$H$2:$H$2536,H11,$I$2:$I$2536,I11,$J$2:$J$2536,J11,$K$2:$K$2536,K11,$L$2:$L$2536,L11,$M$2:$M$2536,M11) -> 1 | O11: =IF(Tabla_control[[#This Row],[Control_duplicados]]>1,"Duplicado","Unico") -> Unico | P11: =IF(OR(I11="",I11<0),"ERROR","OK") -> OK | Q11: =IF(H11>F11,"ERROR","OK") -> OK | R11: =IF(K11>H11,"ERROR","OK") -> OK
A12: 45838 | B12: Cmp-025 | C12: Organic Social | D12: España | E12: Desktop | F12: 169640 | G12: 13188 | H12: 1573 | I12: 3188.1 | J12: 158029.53 | K12: 1309 | L12: Retención | M12: Luis Martín | N12: =COUNTIFS($A$2:$A$2536,A12,$B$2:$B$2536,B12,$C$2:$C$2536,C12,$D$2:$D$2536,D12,$E$2:$E$2536,E12,$F$2:$F$2536,F12,$G$2:$G$2536,G12,$H$2:$H$2536,H12,$I$2:$I$2536,I12,$J$2:$J$2536,J12,$K$2:$K$2536,K12,$L$2:$L$2536,L12,$M$2:$M$2536,M12) -> 1 | O12: =IF(Tabla_control[[#This Row],[Control_duplicados]]>1,"Duplicado","Unico") -> Unico | P12: =IF(OR(I12="",I12<0),"ERROR","OK") -> OK | Q12: =IF(H12>F12,"ERROR","OK") -> OK | R12: =IF(K12>H12,"ERROR","OK") -> OK | U12: Número de registros | V12: =COUNTA(Tabla_control[Fecha]) -> 2535
A13: 45697 | B13: Cmp-006 | C13: Email | D13: España | E13: Desktop | F13: 1815 | G13: 46 | H13: 1 | I13: 54.04 | J13: 192.07 | K13: 0 | L13: Conversión | M13: Marta López | N13: =COUNTIFS($A$2:$A$2536,A13,$B$2:$B$2536,B13,$C$2:$C$2536,C13,$D$2:$D$2536,D13,$E$2:$E$2536,E13,$F$2:$F$2536,F13,$G$2:$G$2536,G13,$H$2:$H$2536,H13,$I$2:$I$2536,I13,$J$2:$J$2536,J13,$K$2:$K$2536,K13,$L$2:$L$2536,L13,$M$2:$M$2536,M13) -> 1 | O13: =IF(Tabla_control[[#This Row],[Control_duplicados]]>1,"Duplicado","Unico") -> Unico | P13: =IF(OR(I13="",I13<0),"ERROR","OK") -> OK | Q13: =IF(H13>F13,"ERROR","OK") -> OK | R13: =IF(K13>H13,"ERROR","OK") -> OK | U13: Registros afectados | V13: =V9 -> 51
A14: 45992 | B14: Cmp-011 | C14: Paid Social | D14: España | E14: Mobile | F14: 58400 | G14: 2796 | H14: 80 | I14: 361.39 | J14: 8867.74 | K14: 71 | L14: Reconocimiento | M14: Ana García | N14: =COUNTIFS($A$2:$A$2536,A14,$B$2:$B$2536,B14,$C$2:$C$2536,C14,$D$2:$D$2536,D14,$E$2:$E$2536,E14,$F$2:$F$2536,F14,$G$2:$G$2536,G14,$H$2:$H$2536,H14,$I$2:$I$2536,I14,$J$2:$J$2536,J14,$K$2:$K$2536,K14,$L$2:$L$2536,L14,$M$2:$M$2536,M14) -> 1 | O14: =IF(Tabla_control[[#This Row],[Control_duplicados]]>1,"Duplicado","Unico") -> Unico | P14: =IF(OR(I14="",I14<0),"ERROR","OK") -> OK | Q14: =IF(H14>F14,"ERROR","OK") -> OK | R14: =IF(K14>H14,"ERROR","OK") -> OK
A15: 45688 | B15: Cmp-018 | C15: Display | D15: México | E15: Desktop | F15: 95164 | G15: 467 | H15: 54 | I15: 899.8 | J15: 8314.82 | K15: 33 | L15: Retención | M15: Carlos Ruiz | N15: =COUNTIFS($A$2:$A$2536,A15,$B$2:$B$2536,B15,$C$2:$C$2536,C15,$D$2:$D$2536,D15,$E$2:$E$2536,E15,$F$2:$F$2536,F15,$G$2:$G$2536,G15,$H$2:$H$2536,H15,$I$2:$I$2536,I15,$J$2:$J$2536,J15,$K$2:$K$2536,K15,$L$2:$L$2536,L15,$M$2:$M$2536,M15) -> 1 | O15: =IF(Tabla_control[[#This Row],[Control_duplicados]]>1,"Duplicado","Unico") -> Unico | P15: =IF(OR(I15="",I15<0),"ERROR","OK") -> OK | Q15: =IF(H15>F15,"ERROR","OK") -> OK | R15: =IF(K15>H15,"ERROR","OK") -> OK | U15: Porcentaje de errores | V15: =V13/V12 -> 0.020118343
A16: 45938 | B16: Cmp-004 | C16: Email | D16: España | E16: Desktop | F16: 163224 | G16: 892 | H16: 116 | I16: 645.97 | J16: 13245.61 | K16: 70 | L16: Reconocimiento | M16: Ana García | N16: =COUNTIFS($A$2:$A$2536,A16,$B$2:$B$2536,B16,$C$2:$C$2536,C16,$D$2:$D$2536,D16,$E$2:$E$2536,E16,$F$2:$F$2536,F16,$G$2:$G$2536,G16,$H$2:$H$2536,H16,$I$2:$I$2536,I16,$J$2:$J$2536,J16,$K$2:$K$2536,K16,$L$2:$L$2536,L16,$M$2:$M$2536,M16) -> 1 | O16: =IF(Tabla_control[[#This Row],[Control_duplicados]]>1,"Duplicado","Unico") -> Unico | P16: =IF(OR(I16="",I16<0),"ERROR","OK") -> OK | Q16: =IF(H16>F16,"ERROR","OK") -> OK | R16: =IF(K16>H16,"ERROR","OK") -> OK
A17: 45780 | B17: Cmp-007 | C17: Affiliate | D17: Francia | E17: Tablet | F17: 44509 | G17: 1756 | H17: 45 | I17: 2433.77 | J17: 1487.74 | K17: 24 | L17: Conversión | M17: Ana García | N17: =COUNTIFS($A$2:$A$2536,A17,$B$2:$B$2536,B17,$C$2:$C$2536,C17,$D$2:$D$2536,D17,$E$2:$E$2536,E17,$F$2:$F$2536,F17,$G$2:$G$2536,G17,$H$2:$H$2536,H17,$I$2:$I$2536,I17,$J$2:$J$2536,J17,$K$2:$K$2536,K17,$L$2:$L$2536,L17,$M$2:$M$2536,M17) -> 1 | O17: =IF(Tabla_control[[#This Row],[Control_duplicados]]>1,"Duplicado","Unico") -> Unico | P17: =IF(OR(I17="",I17<0),"ERROR","OK") -> OK | Q17: =IF(H17>F17,"ERROR","OK") -> OK | R17: =IF(K17>H17,"ERROR","OK") -> OK
A18: 45799 | B18: Cmp-018 | C18: Email | D18: España | E18: Tablet | F18: 49699 | G18: 549 | H18: 14 | I18: 407.19 | J18: 2598.86 | K18: 12 | L18: Conversión | M18: Marta López | N18: =COUNTIFS($A$2:$A$2536,A18,$B$2:$B$2536,B18,$C$2:$C$2536,C18,$D$2:$D$2536,D18,$E$2:$E$2536,E18,$F$2:$F$2536,F18,$G$2:$G$2536,G18,$H$2:$H$2536,H18,$I$2:$I$2536,I18,$J$2:$J$2536,J18,$K$2:$K$2536,K18,$L$2:$L$2536,L18,$M$2:$M$2536,M18) -> 1 | O18: =IF(Tabla_control[[#This Row],[Control_duplicados]]>1,"Duplicado","Unico") -> Unico | P18: =IF(OR(I18="",I18<0),"ERROR","OK") -> OK | Q18: =IF(H18>F18,"ERROR","OK") -> OK | R18: =IF(K18>H18,"ERROR","OK") -> OK
A19: 45738 | B19: Cmp-011 | C19: Affiliate | D19: España | E19: Mobile | F19: 79946 | G19: 6644 | H19: 165 | I19: 12172.18 | J19: 3700.53 | K19: 97 | L19: Retención | M19: Luis Martín | N19: =COUNTIFS($A$2:$A$2536,A19,$B$2:$B$2536,B19,$C$2:$C$2536,C19,$D$2:$D$2536,D19,$E$2:$E$2536,E19,$F$2:$F$2536,F19,$G$2:$G$2536,G19,$H$2:$H$2536,H19,$I$2:$I$2536,I19,$J$2:$J$2536,J19,$K$2:$K$2536,K19,$L$2:$L$2536,L19,$M$2:$M$2536,M19) -> 1 | O19: =IF(Tabla_control[[#This Row],[Control_duplicados]]>1,"Duplicado","Unico") -> Unico | P19: =IF(OR(I19="",I19<0),"ERROR","OK") -> OK | Q19: =IF(H19>F19,"ERROR","OK") -> OK | R19: =IF(K19>H19,"ERROR","OK") -> OK
A20: 45765 | B20: Cmp-022 | C20: Display | D20: México | E20: Mobile | F20: 90643 | G20: 6251 | H20: 607 | I20: 1069.28 | J20: 85223.12 | K20: 473 | L20: Adquisición | M20: Ana García | N20: =COUNTIFS($A$2:$A$2536,A20,$B$2:$B$2536,B20,$C$2:$C$2536,C20,$D$2:$D$2536,D20,$E$2:$E$2536,E20,$F$2:$F$2536,F20,$G$2:$G$2536,G20,$H$2:$H$2536,H20,$I$2:$I$2536,I20,$J$2:$J$2536,J20,$K$2:$K$2536,K20,$L$2:$L$2536,L20,$M$2:$M$2536,M20) -> 1 | O20: =IF(Tabla_control[[#This Row],[Control_duplicados]]>1,"Duplicado","Unico") -> Unico | P20: =IF(OR(I20="",I20<0),"ERROR","OK") -> OK | Q20: =IF(H20>F20,"ERROR","OK") -> OK | R20: =IF(K20>H20,"ERROR","OK") -> OK
A21: 45973 | B21: Cmp-008 | C21: Display | D21: España | E21: Mobile | F21: 78294 | G21: 5439 | H21: 617 | I21: 1504.93 | J21: 130219.67 | K21: 538 | L21: Conversión | M21: Laura Pérez | N21: =COUNTIFS($A$2:$A$2536,A21,$B$2:$B$2536,B21,$C$2:$C$2536,C21,$D$2:$D$2536,D21,$E$2:$E$2536,E21,$F$2:$F$2536,F21,$G$2:$G$2536,G21,$H$2:$H$2536,H21,$I$2:$I$2536,I21,$J$2:$J$2536,J21,$K$2:$K$2536,K21,$L$2:$L$2536,L21,$M$2:$M$2536,M21) -> 1 | O21: =IF(Tabla_control[[#This Row],[Control_duplicados]]>1,"Duplicado","Unico") -> Unico | P21: =IF(OR(I21="",I21<0),"ERROR","OK") -> OK | Q21: =IF(H21>F21,"ERROR","OK") -> OK | R21: =IF(K21>H21,"ERROR","OK") -> OK
A22: 46009 | B22: Cmp-028 | C22: Paid Search | D22: Francia | E22: Desktop | F22: 4759 | G22: 234 | H22: 22 | I22: 333.25 | J22: 2425.61 | K22: 13 | L22: Retención | M22: Ana García | N22: =COUNTIFS($A$2:$A$2536,A22,$B$2:$B$2536,B22,$C$2:$C$2536,C22,$D$2:$D$2536,D22,$E$2:$E$2536,E22,$F$2:$F$2536,F22,$G$2:$G$2536,G22,$H$2:$H$2536,H22,$I$2:$I$2536,I22,$J$2:$J$2536,J22,$K$2:$K$2536,K22,$L$2:$L$2536,L22,$M$2:$M$2536,M22) -> 2 | O22: =IF(Tabla_control[[#This Row],[Control_duplicados]]>1,"Duplicado","Unico") -> Duplicado | P22: =IF(OR(I22="",I22<0),"ERROR","OK") -> OK | Q22: =IF(H22>F22,"ERROR","OK") -> OK | R22: =IF(K22>H22,"ERROR","OK") -> OK
A23: 45791 | B23: Cmp-012 | C23: Organic Social | D23: Francia | E23: Mobile | F23: 7310 | G23: 569 | H23: 77 | I23: 65.92 | J23: 3364.24 | K23: 59 | L23: Reconocimiento | M23: Luis Martín | N23: =COUNTIFS($A$2:$A$2536,A23,$B$2:$B$2536,B23,$C$2:$C$2536,C23,$D$2:$D$2536,D23,$E$2:$E$2536,E23,$F$2:$F$2536,F23,$G$2:$G$2536,G23,$H$2:$H$2536,H23,$I$2:$I$2536,I23,$J$2:$J$2536,J23,$K$2:$K$2536,K23,$L$2:$L$2536,L23,$M$2:$M$2536,M23) -> 1 | O23: =IF(Tabla_control[[#This Row],[Control_duplicados]]>1,"Duplicado","Unico") -> Unico | P23: =IF(OR(I23="",I23<0),"ERROR","OK") -> OK | Q23: =IF(H23>F23,"ERROR","OK") -> OK | R23: =IF(K23>H23,"ERROR","OK") -> OK
A24: 45989 | B24: Cmp-025 | C24: Email | D24: Portugal | E24: Mobile | F24: 42237 | G24: 591 | H24: 35 | I24: 506.92 | J24: 7159.42 | K24: 17 | L24: Reconocimiento | M24: Ana García | N24: =COUNTIFS($A$2:$A$2536,A24,$B$2:$B$2536,B24,$C$2:$C$2536,C24,$D$2:$D$2536,D24,$E$2:$E$2536,E24,$F$2:$F$2536,F24,$G$2:$G$2536,G24,$H$2:$H$2536,H24,$I$2:$I$2536,I24,$J$2:$J$2536,J24,$K$2:$K$2536,K24,$L$2:$L$2536,L24,$M$2:$M$2536,M24) -> 1 | O24: =IF(Tabla_control[[#This Row],[Control_duplicados]]>1,"Duplicado","Unico") -> Unico | P24: =IF(OR(I24="",I24<0),"ERROR","OK") -> OK | Q24: =IF(H24>F24,"ERROR","OK") -> OK | R24: =IF(K24>H24,"ERROR","OK") -> OK
A25: 45829 | B25: Cmp-002 | C25: Display | D25: Portugal | E25: Mobile | F25: 7568 | G25: 600 | H25: 21 | I25: 703.66 | J25: 3621.93 | K25: 15 | L25: Adquisición | M25: Ana García | N25: =COUNTIFS($A$2:$A$2536,A25,$B$2:$B$2536,B25,$C$2:$C$2536,C25,$D$2:$D$2536,D25,$E$2:$E$2536,E25,$F$2:$F$2536,F25,$G$2:$G$2536,G25,$H$2:$H$2536,H25,$I$2:$I$2536,I25,$J$2:$J$2536,J25,$K$2:$K$2536,K25,$L$2:$L$2536,L25,$M$2:$M$2536,M25) -> 1 | O25: =IF(Tabla_control[[#This Row],[Control_duplicados]]>1,"Duplicado","Unico") -> Unico | P25: =IF(OR(I25="",I25<0),"ERROR","OK") -> OK | Q25: =IF(H25>F25,"ERROR","OK") -> OK | R25: =IF(K25>H25,"ERROR","OK") -> OK
A26: 45860 | B26: Cmp-028 | C26: Display | D26: España | E26: Mobile | F26: 105858 | G26: 9130 | H26: 579 | I26: 8905.21 | J26: 70771.17 | K26: 511 | L26: Adquisición | M26: Carlos Ruiz | N26: =COUNTIFS($A$2:$A$2536,A26,$B$2:$B$2536,B26,$C$2:$C$2536,C26,$D$2:$D$2536,D26,$E$2:$E$2536,E26,$F$2:$F$2536,F26,$G$2:$G$2536,G26,$H$2:$H$2536,H26,$I$2:$I$2536,I26,$J$2:$J$2536,J26,$K$2:$K$2536,K26,$L$2:$L$2536,L26,$M$2:$M$2536,M26) -> 1 | O26: =IF(Tabla_control[[#This Row],[Control_duplicados]]>1,"Duplicado","Unico") -> Unico | P26: =IF(OR(I26="",I26<0),"ERROR","OK") -> OK | Q26: =IF(H26>F26,"ERROR","OK") -> OK | R26: =IF(K26>H26,"ERROR","OK") -> OK
A27: 45844 | B27: Cmp-019 | C27: Display | D27: España | E27: Mobile | F27: 103769 | G27: 4146 | H27: 299 | I27: 1850.07 | J27: 12653.93 | K27: 235 | L27: Retención | M27: Luis Martín | N27: =COUNTIFS($A$2:$A$2536,A27,$B$2:$B$2536,B27,$C$2:$C$2536,C27,$D$2:$D$2536,D27,$E$2:$E$2536,E27,$F$2:$F$2536,F27,$G$2:$G$2536,G27,$H$2:$H$2536,H27,$I$2:$I$2536,I27,$J$2:$J$2536,J27,$K$2:$K$2536,K27,$L$2:$L$2536,L27,$M$2:$M$2536,M27) -> 1 | O27: =IF(Tabla_control[[#This Row],[Control_duplicados]]>1,"Duplicado","Unico") -> Unico | P27: =IF(OR(I27="",I27<0),"ERROR","OK") -> OK | Q27: =IF(H27>F27,"ERROR","OK") -> OK | R27: =IF(K27>H27,"ERROR","OK") -> OK
... A92: 45834 | B92: Cmp-020 | C92: Paid Social | D92: Italia | E92: Mobile | F92: 168186 | G92: 12846 | H92: 248 | I92: 11843.19 | J92: 16511.03 | K92: 193 | L92: Conversión | M92: Laura Pérez | N92: =COUNTIFS($A$2:$A$2536,A92,$B$2:$B$2536,B92,$C$2:$C$2536,C92,$D$2:$D$2536,D92,$E$2:$E$2536,E92,$F$2:$F$2536,F92,$G$2:$G$2536,G92,$H$2:$H$2536,H92,$I$2:$I$2536,I92,$J$2:$J$2536,J92,$K$2:$K$2536,K92,$L$2:$L$2536,L92,$M$2:$M$2536,M92) -> 1 | O92: =IF(Tabla_control[[#This Row],[Control_duplicados]]>1,"Duplicado","Unico") -> Unico | P92: =IF(OR(I92="",I92<0),"ERROR","OK") -> OK | Q92: =IF(H92>F92,"ERROR","OK") -> OK | R92: =IF(K92>H92,"ERROR","OK") -> OK
A93: 45719 | B93: Cmp-024 | C93: Organic Social | D93: Francia | E93: Desktop | F93: 125337 | G93: 4913 | H93: 247 | J93: 19111.59 | K93: 173 | L93: Retención | M93: Ana García | N93: =COUNTIFS($A$2:$A$2536,A93,$B$2:$B$2536,B93,$C$2:$C$2536,C93,$D$2:$D$2536,D93,$E$2:$E$2536,E93,$F$2:$F$2536,F93,$G$2:$G$2536,G93,$H$2:$H$2536,H93,$I$2:$I$2536,I93,$J$2:$J$2536,J93,$K$2:$K$2536,K93,$L$2:$L$2536,L93,$M$2:$M$2536,M93) -> 0 | O93: =IF(Tabla_control[[#This Row],[Control_duplicados]]>1,"Duplicado","Unico") -> Unico | P93: =IF(OR(I93="",I93<0),"ERROR","OK") -> ERROR | Q93: =IF(H93>F93,"ERROR","OK") -> OK | R93: =IF(K93>H93,"ERROR","OK") -> OK
A94: 45770 | B94: Cmp-008 | C94: Affiliate | D94: Portugal | E94: Mobile | F94: 156107 | G94: 10929 | H94: 151 | I94: 14137.01 | J94: 25165.32 | K94: 106 | L94: Retención | M94: Carlos Ruiz | N94: =COUNTIFS($A$2:$A$2536,A94,$B$2:$B$2536,B94,$C$2:$C$2536,C94,$D$2:$D$2536,D94,$E$2:$E$2536,E94,$F$2:$F$2536,F94,$G$2:$G$2536,G94,$H$2:$H$2536,H94,$I$2:$I$2536,I94,$J$2:$J$2536,J94,$K$2:$K$2536,K94,$L$2:$L$2536,L94,$M$2:$M$2536,M94) -> 1 | O94: =IF(Tabla_control[[#This Row],[Control_duplicados]]>1,"Duplicado","Unico") -> Unico | P94: =IF(OR(I94="",I94<0),"ERROR","OK") -> OK | Q94: =IF(H94>F94,"ERROR","OK") -> OK | R94: =IF(K94>H94,"ERROR","OK") -> OK
A95: 45963 | B95: Cmp-026 | C95: Paid Social | D95: Francia | E95: Mobile | F95: 107920 | G95: 2646 | H95: 80 | I95: 313.34 | J95: 16240.95 | K95: 70 | L95: Reconocimiento | M95: Laura Pérez | N95: =COUNTIFS($A$2:$A$2536,A95,$B$2:$B$2536,B95,$C$2:$C$2536,C95,$D$2:$D$2536,D95,$E$2:$E$2536,E95,$F$2:$F$2536,F95,$G$2:$G$2536,G95,$H$2:$H$2536,H95,$I$2:$I$2536,I95,$J$2:$J$2536,J95,$K$2:$K$2536,K95,$L$2:$L$2536,L95,$M$2:$M$2536,M95) -> 2 | O95: =IF(Tabla_control[[#This Row],[Control_duplicados]]>1,"Duplicado","Unico") -> Duplicado | P95: =IF(OR(I95="",I95<0),"ERROR","OK") -> OK | Q95: =IF(H95>F95,"ERROR","OK") -> OK | R95: =IF(K95>H95,"ERROR","OK") -> OK
A96: 45830 | B96: Cmp-019 | C96: Paid Search | D96: España | E96: Tablet | F96: 149923 | G96: 13315 | H96: 1463 | I96: 10768.8 | J96: 89544.3 | K96: 1298 | L96: Conversión | M96: Luis Martín | N96: =COUNTIFS($A$2:$A$2536,A96,$B$2:$B$2536,B96,$C$2:$C$2536,C96,$D$2:$D$2536,D96,$E$2:$E$2536,E96,$F$2:$F$2536,F96,$G$2:$G$2536,G96,$H$2:$H$2536,H96,$I$2:$I$2536,I96,$J$2:$J$2536,J96,$K$2:$K$2536,K96,$L$2:$L$2536,L96,$M$2:$M$2536,M96) -> 1 | O96: =IF(Tabla_control[[#This Row],[Control_duplicados]]>1,"Duplicado","Unico") -> Unico | P96: =IF(OR(I96="",I96<0),"ERROR","OK") -> OK | Q96: =IF(H96>F96,"ERROR","OK") -> OK | R96: =IF(K96>H96,"ERROR","OK") -> OK
A97: 45888 | B97: Cmp-022 | C97: Paid Search | D97: Portugal | E97: Desktop | F97: 153656 | G97: 6271 | H97: 500 | I97: 12777.65 | J97: 13674.92 | K97: 260 | L97: Reconocimiento | M97: Laura Pérez | N97: =COUNTIFS($A$2:$A$2536,A97,$B$2:$B$2536,B97,$C$2:$C$2536,C97,$D$2:$D$2536,D97,$E$2:$E$2536,E97,$F$2:$F$2536,F97,$G$2:$G$2536,G97,$H$2:$H$2536,H97,$I$2:$I$2536,I97,$J$2:$J$2536,J97,$K$2:$K$2536,K97,$L$2:$L$2536,L97,$M$2:$M$2536,M97) -> 1 | O97: =IF(Tabla_control[[#This Row],[Control_duplicados]]>1,"Duplicado","Unico") -> Unico | P97: =IF(OR(I97="",I97<0),"ERROR","OK") -> OK | Q97: =IF(H97>F97,"ERROR","OK") -> OK | R97: =IF(K97>H97,"ERROR","OK") -> OK
A98: 45826 | B98: Cmp-007 | C98: Affiliate | D98: España | E98: Desktop | F98: 50750 | G98: 742 | H98: 33 | I98: 121.99 | J98: 1482.78 | K98: 22 | L98: Conversión | M98: Ana García | N98: =COUNTIFS($A$2:$A$2536,A98,$B$2:$B$2536,B98,$C$2:$C$2536,C98,$D$2:$D$2536,D98,$E$2:$E$2536,E98,$F$2:$F$2536,F98,$G$2:$G$2536,G98,$H$2:$H$2536,H98,$I$2:$I$2536,I98,$J$2:$J$2536,J98,$K$2:$K$2536,K98,$L$2:$L$2536,L98,$M$2:$M$2536,M98) -> 1 | O98: =IF(Tabla_control[[#This Row],[Control_duplicados]]>1,"Duplicado","Unico") -> Unico | P98: =IF(OR(I98="",I98<0),"ERROR","OK") -> OK | Q98: =IF(H98>F98,"ERROR","OK") -> OK | R98: =IF(K98>H98,"ERROR","OK") -> OK
A99: 45854 | B99: Cmp-022 | C99: Paid Search | D99: Portugal | E99: Mobile | F99: 14125 | G99: 603 | H99: 7 | I99: 544.15 | J99: 785.17 | K99: 5 | L99: Adquisición | M99: Laura Pérez | N99: =COUNTIFS($A$2:$A$2536,A99,$B$2:$B$2536,B99,$C$2:$C$2536,C99,$D$2:$D$2536,D99,$E$2:$E$2536,E99,$F$2:$F$2536,F99,$G$2:$G$2536,G99,$H$2:$H$2536,H99,$I$2:$I$2536,I99,$J$2:$J$2536,J99,$K$2:$K$2536,K99,$L$2:$L$2536,L99,$M$2:$M$2536,M99) -> 1 | O99: =IF(Tabla_control[[#This Row],[Control_duplicados]]>1,"Duplicado","Unico") -> Unico | P99: =IF(OR(I99="",I99<0),"ERROR","OK") -> OK | Q99: =IF(H99>F99,"ERROR","OK") -> OK | R99: =IF(K99>H99,"ERROR","OK") -> OK
A100: 45930 | B100: Cmp-018 | C100: Paid Social | D100: España | E100: Desktop | F100: 4605 | G100: 133 | H100: 16 | I100: 71.82 | J100: 2255.32 | K100: 10 | L100: Conversión | M100: Luis Martín | N100: =COUNTIFS($A$2:$A$2536,A100,$B$2:$B$2536,B100,$C$2:$C$2536,C100,$D$2:$D$2536,D100,$E$2:$E$2536,E100,$F$2:$F$2536,F100,$G$2:$G$2536,G100,$H$2:$H$2536,H100,$I$2:$I$2536,I100,$J$2:$J$2536,J100,$K$2:$K$2536,K100,$L$2:$L$2536,L100,$M$2:$M$2536,M100) -> 1 | O100: =IF(Tabla_control[[#This Row],[Control_duplicados]]>1,"Duplicado","Unico") -> Unico | P100: =IF(OR(I100="",I100<0),"ERROR","OK") -> OK | Q100: =IF(H100>F100,"ERROR","OK") -> OK | R100: =IF(K100>H100,"ERROR","OK") -> OK
A101: 45922 | B101: Cmp-013 | C101: Affiliate | D101: España | E101: Mobile | F101: 110457 | G101: 2756 | H101: 71 | I101: 3572.7 | J101: 10415.2 | K101: 38 | L101: Reconocimiento | M101: Marta López | N101: =COUNTIFS($A$2:$A$2536,A101,$B$2:$B$2536,B101,$C$2:$C$2536,C101,$D$2:$D$2536,D101,$E$2:$E$2536,E101,$F$2:$F$2536,F101,$G$2:$G$2536,G101,$H$2:$H$2536,H101,$I$2:$I$2536,I101,$J$2:$J$2536,J101,$K$2:$K$2536,K101,$L$2:$L$2536,L101,$M$2:$M$2536,M101) -> 1 | O101: =IF(Tabla_control[[#This Row],[Control_duplicados]]>1,"Duplicado","Unico") -> Unico | P101: =IF(OR(I101="",I101<0),"ERROR","OK") -> OK | Q101: =IF(H101>F101,"ERROR","OK") -> OK | R101: =IF(K101>H101,"ERROR","OK") -> OK
A102: 46012 | B102: Cmp-009 | C102: Email | D102: Italia | E102: Desktop | F102: 9726 | G102: 296 | H102: 26 | I102: 102.51 | J102: 2620.52 | K102: 22 | L102: Reconocimiento | M102: Laura Pérez | N102: =COUNTIFS($A$2:$A$2536,A102,$B$2:$B$2536,B102,$C$2:$C$2536,C102,$D$2:$D$2536,D102,$E$2:$E$2536,E102,$F$2:$F$2536,F102,$G$2:$G$2536,G102,$H$2:$H$2536,H102,$I$2:$I$2536,I102,$J$2:$J$2536,J102,$K$2:$K$2536,K102,$L$2:$L$2536,L102,$M$2:$M$2536,M102) -> 1 | O102: =IF(Tabla_control[[#This Row],[Control_duplicados]]>1,"Duplicado","Unico") -> Unico | P102: =IF(OR(I102="",I102<0),"ERROR","OK") -> OK | Q102: =IF(H102>F102,"ERROR","OK") -> OK | R102: =IF(K102>H102,"ERROR","OK") -> OK
A103: 45672 | B103: Cmp-027 | C103: Display | D103: España | E103: Desktop | F103: 164689 | G103: 8202 | H103: 215 | I103: 17165.28 | J103: 9987.1 | K103: 156 | L103: Conversión | M103: Luis Martín | N103: =COUNTIFS($A$2:$A$2536,A103,$B$2:$B$2536,B103,$C$2:$C$2536,C103,$D$2:$D$2536,D103,$E$2:$E$2536,E103,$F$2:$F$2536,F103,$G$2:$G$2536,G103,$H$2:$H$2536,H103,$I$2:$I$2536,I103,$J$2:$J$2536,J103,$K$2:$K$2536,K103,$L$2:$L$2536,L103,$M$2:$M$2536,M103) -> 1 | O103: =IF(Tabla_control[[#This Row],[Control_duplicados]]>1,"Duplicado","Unico") -> Unico | P103: =IF(OR(I103="",I103<0),"ERROR","OK") -> OK | Q103: =IF(H103>F103,"ERROR","OK") -> OK | R103: =IF(K103>H103,"ERROR","OK") -> OK
A104: 45969 | B104: Cmp-011 | C104: Email | D104: Francia | E104: Desktop | F104: 24391 | G104: 1360 | H104: 179 | I104: 2162.02 | J104: 9403.73 | K104: 102 | L104: Conversión | M104: Carlos Ruiz | N104: =COUNTIFS($A$2:$A$2536,A104,$B$2:$B$2536,B104,$C$2:$C$2536,C104,$D$2:$D$2536,D104,$E$2:$E$2536,E104,$F$2:$F$2536,F104,$G$2:$G$2536,G104,$H$2:$H$2536,H104,$I$2:$I$2536,I104,$J$2:$J$2536,J104,$K$2:$K$2536,K104,$L$2:$L$2536,L104,$M$2:$M$2536,M104) -> 1 | O104: =IF(Tabla_control[[#This Row],[Control_duplicados]]>1,"Duplicado","Unico") -> Unico | P104: =IF(OR(I104="",I104<0),"ERROR","OK") -> OK | Q104: =IF(H104>F104,"ERROR","OK") -> OK | R104: =IF(K104>H104,"ERROR","OK") -> OK
...

Sheet Datos limpios 
A1: Fecha | B1: ID_Campaña | C1: Canal | D1: País | E1: Dispositivo | F1: Impresiones | G1: Clics | H1: Conversiones | I1: Gasto_EUR | J1: Ingresos_EUR | K1: Nuevos_Clientes | L1: Tipo_Campaña | M1: Responsable
A2: 45868 | B2: Cmp-002 | C2: Email | D2: México | E2: Desktop | F2: 129041 | G2: 9255 | H2: 1081 | I2: 4728.14 | J2: 195401.22 | K2: 926 | L2: Adquisición | M2: Carlos Ruiz
A3: 45779 | B3: Cmp-009 | C3: Paid Search | D3: Italia | E3: Desktop | F3: 50677 | G3: 4047 | H3: 409 | I3: 6481.73 | J3: 65100.85 | K3: 249 | L3: Retención | M3: Luis Martín
A4: 45662 | B4: Cmp-009 | C4: Email | D4: Francia | E4: Desktop | F4: 12070 | G4: 959 | H4: 57 | I4: 1465.19 | J4: 7772.79 | K4: 31 | L4: Retención | M4: Laura Pérez | O4: Número de registros | P4: =COUNTA(Tabla_limpios[Fecha]) -> 2484
A5: 45815 | B5: Cmp-002 | C5: Affiliate | D5: España | E5: Mobile | F5: 114121 | G5: 890 | H5: 114 | I5: 1196.8 | J5: 24221.44 | K5: 52 | L5: Adquisición | M5: Luis Martín
A6: 45916 | B6: Cmp-026 | C6: Paid Search | D6: Portugal | E6: Desktop | F6: 123994 | G6: 5563 | H6: 308 | I6: 1315.48 | J6: 47341.08 | K6: 254 | L6: Adquisición | M6: Luis Martín
A7: 45934 | B7: Cmp-022 | C7: Paid Social | D7: Portugal | E7: Tablet | F7: 170534 | G7: 7543 | H7: 96 | I7: 10662.79 | J7: 15691.35 | K7: 51 | L7: Adquisición | M7: Carlos Ruiz
A8: 45828 | B8: Cmp-015 | C8: Email | D8: Francia | E8: Tablet | F8: 84579 | G8: 3855 | H8: 121 | I8: 7967.14 | J8: 12733.03 | K8: 58 | L8: Reconocimiento | M8: Marta López
A9: 45941 | B9: Cmp-004 | C9: Affiliate | D9: Portugal | E9: Mobile | F9: 125454 | G9: 7459 | H9: 507 | I9: 14866.14 | J9: 74384.02 | K9: 356 | L9: Conversión | M9: Laura Pérez
A10: 45908 | B10: Cmp-017 | C10: Paid Search | D10: Portugal | E10: Desktop | F10: 147026 | G10: 2076 | H10: 174 | I10: 574.55 | J10: 13381.79 | K10: 125 | L10: Conversión | M10: Luis Martín
A11: 45974 | B11: Cmp-002 | C11: Display | D11: Francia | E11: Mobile | F11: 8375 | G11: 469 | H11: 33 | I11: 672.99 | J11: 5104.23 | K11: 18 | L11: Conversión | M11: Marta López
A12: 45838 | B12: Cmp-025 | C12: Organic Social | D12: España | E12: Desktop | F12: 169640 | G12: 13188 | H12: 1573 | I12: 3188.1 | J12: 158029.53 | K12: 1309 | L12: Retención | M12: Luis Martín
A13: 45697 | B13: Cmp-006 | C13: Email | D13: España | E13: Desktop | F13: 1815 | G13: 46 | H13: 1 | I13: 54.04 | J13: 192.07 | K13: 0 | L13: Conversión | M13: Marta López
A14: 45992 | B14: Cmp-011 | C14: Paid Social | D14: España | E14: Mobile | F14: 58400 | G14: 2796 | H14: 80 | I14: 361.39 | J14: 8867.74 | K14: 71 | L14: Reconocimiento | M14: Ana García
A15: 45688 | B15: Cmp-018 | C15: Display | D15: México | E15: Desktop | F15: 95164 | G15: 467 | H15: 54 | I15: 899.8 | J15: 8314.82 | K15: 33 | L15: Retención | M15: Carlos Ruiz
A16: 45938 | B16: Cmp-004 | C16: Email | D16: España | E16: Desktop | F16: 163224 | G16: 892 | H16: 116 | I16: 645.97 | J16: 13245.61 | K16: 70 | L16: Reconocimiento | M16: Ana García
... A2485: 45793 | B2485: Cmp-012 | C2485: Email | D2485: Portugal | E2485: Mobile | F2485: 3038 | G2485: 193 | H2485: 24 | I2485: 303.76 | J2485: 4454.33 | K2485: 18 | L2485: Adquisición | M2485: Luis Martín

Sheet Datos nuevas columnas
A1: Fecha | B1: ID_Campaña | C1: Canal | D1: País | E1: Dispositivo | F1: Impresiones | G1: Clics | H1: Conversiones | I1: Gasto_EUR | J1: Ingresos_EUR | K1: Nuevos_Clientes | L1: Tipo_Campaña | M1: Responsable | N1: CTR | O1: Tasa de conversión | P1: CPC | Q1: CPA | R1: ROAS | S1: %ROAS | T1: Etiqueta Canal-País | U1: Año | V1: Número mes | W1: Mes | X1: Día de la semana | Y1: Rendimiento | Z1: Seguimiento | AA1: ROAS Objetivo | AB1: CPC Objetivo
A2: 45868 | B2: Cmp-002 | C2: Email | D2: México | E2: Desktop | F2: 129041 | G2: 9255 | H2: 1081 | I2: 4728.14 | J2: 195401.22 | K2: 926 | L2: Adquisición | M2: Carlos Ruiz | N2: =IFERROR(G2/F2,0) -> 0.071721391 | O2: =IFERROR(H2/G2,0) -> 0.11680173 | P2: =IFERROR(I2/G2,0) -> 0.51087412 | Q2: =IFERROR(I2/H2,0) -> 4.3738575 | R2: =IFERROR(J2/I2,0) -> 41.327291 | S2: =Tabla_nuevas_columnas[[#This Row],[ROAS]] -> 41.327291 | T2: =_xlfn.CONCAT(C2,"-",D2) -> Email-México | U2: =YEAR(A2) -> 2025 | V2: =MONTH(A2) -> 7 | W2: =PROPER(TEXT(A2,"mmmm")) -> Julio | X2: =PROPER(TEXT(A2,"dddd")) -> Miércoles | Y2: {=_xlfn.IFS(R2>10,"Excelente",R2>=5,"Bueno",R2>=2,"Débil",R2<2,"Deficiente")} -> Excelente | Z2: =IF(AND(R2<2,Q2>=100),"Revisar","OK") -> OK | AA2: =_xlfn.XLOOKUP(C2,'Preguntas de negocio'!$C$114:$C$119,'Preguntas de negocio'!$D$114:$D$119,0) -> 5.5 | AB2: =VLOOKUP(C2,'Preguntas de negocio'!$C$121:$D$127,2,FALSE) -> 0.65
A3: 45779 | B3: Cmp-009 | C3: Paid Search | D3: Italia | E3: Desktop | F3: 50677 | G3: 4047 | H3: 409 | I3: 6481.73 | J3: 65100.85 | K3: 249 | L3: Retención | M3: Luis Martín | N3: =IFERROR(G3/F3,0) -> 0.079858713 | O3: =IFERROR(H3/G3,0) -> 0.10106252 | P3: =IFERROR(I3/G3,0) -> 1.6016135 | Q3: =IFERROR(I3/H3,0) -> 15.847751 | R3: =IFERROR(J3/I3,0) -> 10.043746 | S3: =Tabla_nuevas_columnas[[#This Row],[ROAS]] -> 10.043746 | T3: =_xlfn.CONCAT(C3,"-",D3) -> Paid Search-Italia | U3: =YEAR(A3) -> 2025 | V3: =MONTH(A3) -> 5 | W3: =PROPER(TEXT(A3,"mmmm")) -> Mayo | X3: =PROPER(TEXT(A3,"dddd")) -> Viernes | Y3: {=_xlfn.IFS(R3>10,"Excelente",R3>=5,"Bueno",R3>=2,"Débil",R3<2,"Deficiente")} -> Excelente | Z3: =IF(AND(R3<2,Q3>=100),"Revisar","OK") -> OK | AA3: =_xlfn.XLOOKUP(C3,'Preguntas de negocio'!$C$114:$C$119,'Preguntas de negocio'!$D$114:$D$119,0) -> 5 | AB3: =VLOOKUP(C3,'Preguntas de negocio'!$C$121:$D$127,2,FALSE) -> 1.1
A4: 45662 | B4: Cmp-009 | C4: Email | D4: Francia | E4: Desktop | F4: 12070 | G4: 959 | H4: 57 | I4: 1465.19 | J4: 7772.79 | K4: 31 | L4: Retención | M4: Laura Pérez | N4: =IFERROR(G4/F4,0) -> 0.07945319 | O4: =IFERROR(H4/G4,0) -> 0.059436913 | P4: =IFERROR(I4/G4,0) -> 1.5278311 | Q4: =IFERROR(I4/H4,0) -> 25.705088 | R4: =IFERROR(J4/I4,0) -> 5.3049707 | S4: =Tabla_nuevas_columnas[[#This Row],[ROAS]] -> 5.3049707 | T4: =_xlfn.CONCAT(C4,"-",D4) -> Email-Francia | U4: =YEAR(A4) -> 2025 | V4: =MONTH(A4) -> 1 | W4: =PROPER(TEXT(A4,"mmmm")) -> Enero | X4: =PROPER(TEXT(A4,"dddd")) -> Domingo | Y4: {=_xlfn.IFS(R4>10,"Excelente",R4>=5,"Bueno",R4>=2,"Débil",R4<2,"Deficiente")} -> Bueno | Z4: =IF(AND(R4<2,Q4>=100),"Revisar","OK") -> OK | AA4: =_xlfn.XLOOKUP(C4,'Preguntas de negocio'!$C$114:$C$119,'Preguntas de negocio'!$D$114:$D$119,0) -> 5.5 | AB4: =VLOOKUP(C4,'Preguntas de negocio'!$C$121:$D$127,2,FALSE) -> 0.65
